Workbook

Sheet Cara Pengisian
A2: Sheet Berwarna Kuning Wajib Diisi dan Di update
A4: Untuk Sheet Tgl Maintenance untuk Kontrak
A5: 1. Update Data Pada Kolom G sesuai tanggal Maintenance Jika Sudah Pada kolom H di Tulis "Done" Agar tanggal Pada Komom M dapat Terupdate
A6: 2. Untuk Maintenance Ke 2 Bisa Di update Pada Kolom I dan pada Kolom J ditulis "Done" adar tanggal Pada Kolom M Terupdate
A7: 3. Untuk Maiantenace ke 3 Bisa Di update pada Kolom K Dika Sudah Pada Kolom L Di tulis "Done" Agar Pada Kolom M Terupdate
A9: Sheet Data Garansi
A10: 1. Di update Setiap Bulan dari Kolom B sd E Setiap Ada BAST
A11: 2. lalu update Kolom G tanggal pada saat ingin mengecek agar data I dapat Terupdate Garansi atau tidaknya
A12: 3. untuk Kolom F , H dan I Di Copy Paste Saja
A14: Data Counting Free
A15: 1. Data Di Kolom B sd E Di Update Setiap Ada BAST Khusus untuk Customer Baru Install dan memiliki Free Maintenance
A16: 2. Data Kolom G sd M Di update Setiap Ada Kunjungan
... A25: 2. Jika Kolom G sdh Dikunjungi pada Kolom H di update done agar Kolom m Terupdate tgl berikutnya

Sheet Main
A1: No | B1: Jenis Lift | C1: Code Lift | D1: Tgl BAST | F1: Nama Cust | G1: Area | H1: Free Maintenance | I1: Maintenance Kontrak | J1: Garansi atau Tidak | K1: Tgl Maintenance Free | L1: Tgl Maintenance Berjalan
A2: 1 | B2: Domo Flex | C2: 21/0670 | D2: 44201 | E2: =TEXT(L2,"mmm") -> May | F2: Ir. H. Awan Hermawan Purwadinata MT, Bandung | G2: Bandung | H2: =VLOOKUP(F2,'Counting Free'!$B:$F,4,0) -> 0 | I2: =VLOOKUP(F2,'Counting Kontrak'!B:E,4,0) -> 0 | J2: =VLOOKUP(F2,'Data Garansi'!$E:$I,5,0) -> Tidak | K2: =VLOOKUP(F2,'Tgl MC Free'!B:M,8,0) -> 45978 | L2: =VLOOKUP(F2,'Tgl Maintenance untuk Kontrak'!$D:$M,10,0) -> 45798 | M2: =TEXT(L2,"mmm") -> May
A3: 2 | B3: Galactic | C3: 21/0745 | D3: 44255 | E3: =TEXT(L3,"mmm") -> May | F3: Syamsuardi Alpat (Sudirman) | G3: Makasar | H3: =VLOOKUP(F3,'Counting Free'!$B:$F,4,0) -> 0 | I3: =VLOOKUP(F3,'Counting Kontrak'!B:E,4,0) -> 0 | J3: =VLOOKUP(F3,'Data Garansi'!$E:$I,5,0) -> Tidak | K3: =VLOOKUP(F3,'Tgl MC Free'!B:M,8,0) -> 45980 | L3: =VLOOKUP(F3,'Tgl Maintenance untuk Kontrak'!$D:$M,10,0) -> 45800 | M3: =TEXT(L3,"mmm") -> May
A4: 3 | B4: Domo Flex | C4: 21/0227 | D4: 44400 | F4: Hendra Dwi Kurniawan | G4: Jakarta Utara | H4: =VLOOKUP(F4,'Counting Free'!$B:$F,4,0) -> 2 | I4: =VLOOKUP(F4,'Counting Kontrak'!B:E,4,0) -> 0 | J4: =VLOOKUP(F4,'Data Garansi'!$E:$I,5,0) -> Tidak | K4: =VLOOKUP(F4,'Tgl MC Free'!B:M,8,0) -> 45790 | L4: =VLOOKUP(F4,'Tgl Maintenance untuk Kontrak'!$D:$M,10,0) -> 45610 | M4: =TEXT(L4,"mmm") -> Nov
A5: 4 | B5: Indomo Shaft | C5: 21/0258 | D5: 44428 | F5: CV Jawa Indah (Ibu Yuli), Samarinda, Kal-Tim | G5: Kalimantan Timur | H5: =VLOOKUP(F5,'Counting Free'!$B:$F,4,0) -> 1 | I5: =VLOOKUP(F5,'Counting Kontrak'!B:E,4,0) -> 0 | J5: =VLOOKUP(F5,'Data Garansi'!$E:$I,5,0) -> Tidak | K5: =VLOOKUP(F5,'Tgl MC Free'!B:M,8,0) -> 45536 | L5: =VLOOKUP(F5,'Tgl Maintenance untuk Kontrak'!$D:$M,10,0) -> 45356 | M5: =TEXT(L5,"mmm") -> Mar
A6: 5 | B6: Pve 37 midio | C6: PVE | D6: 44435 | E6: =TEXT(L6,"mmm") -> - | F6: PT. Yolita Plasinto Pratama ( Ida) | G6: Jakarta Utara | H6: =VLOOKUP(F6,'Counting Free'!$B:$F,4,0) -> 2 | I6: =VLOOKUP(F6,'Counting Kontrak'!B:E,4,0) -> 13 | J6: =VLOOKUP(F6,'Data Garansi'!$E:$I,5,0) -> Tidak | K6: =VLOOKUP(F6,'Tgl MC Free'!B:M,8,0) -> 46160 | L6: =VLOOKUP(F6,'Tgl Maintenance untuk Kontrak'!$D:$M,10,0) -> - | M6: =TEXT(L6,"mmm") -> -
A7: 6 | B7: Domo Flex | C7: 21/0455 | D7: 44474 | E7: =TEXT(L7,"mmm") -> Jun | F7: CV Pije Peter Cheryl (Andi) | G7: Jakarta Selatan | H7: =VLOOKUP(F7,'Counting Free'!$B:$F,4,0) -> 2 | I7: =VLOOKUP(F7,'Counting Kontrak'!B:E,4,0) -> 0 | J7: =VLOOKUP(F7,'Data Garansi'!$E:$I,5,0) -> Tidak | K7: =VLOOKUP(F7,'Tgl MC Free'!B:M,8,0) -> 46045 | L7: =VLOOKUP(F7,'Tgl Maintenance untuk Kontrak'!$D:$M,10,0) -> 46193 | M7: =TEXT(L7,"mmm") -> Jun
A8: 7 | B8: Domo Flex | C8: 21/0542 | D8: 44490 | E8: =TEXT(L8,"mmm") -> Jan | F8: Esther Indrawati | G8: Surabaya | H8: =VLOOKUP(F8,'Counting Free'!$B:$F,4,0) -> 2 | I8: =VLOOKUP(F8,'Counting Kontrak'!B:E,4,0) -> 0 | J8: =VLOOKUP(F8,'Data Garansi'!$E:$I,5,0) -> Tidak | K8: =VLOOKUP(F8,'Tgl MC Free'!B:M,8,0) -> 45859 | L8: =VLOOKUP(F8,'Tgl Maintenance untuk Kontrak'!$D:$M,10,0) -> 45679 | M8: =TEXT(L8,"mmm") -> Jan
A9: 8 | B9: Domo Flex | C9: 21/0375 | D9: 44517 | E9: =TEXT(L9,"mmm") -> May | F9: PT. Bertie Sukses Makmur (Andi) | G9: Jakarta Selatan | H9: =VLOOKUP(F9,'Counting Free'!$B:$F,4,0) -> 2 | I9: =VLOOKUP(F9,'Counting Kontrak'!B:E,4,0) -> 0 | J9: =VLOOKUP(F9,'Data Garansi'!$E:$I,5,0) -> Tidak | K9: =VLOOKUP(F9,'Tgl MC Free'!B:M,8,0) -> 46119 | L9: =VLOOKUP(F9,'Tgl Maintenance untuk Kontrak'!$D:$M,10,0) -> 46144 | M9: =TEXT(L9,"mmm") -> May
A10: 9 | B10: Domo Flex | C10: 21/0676 | D10: 44525 | E10: =TEXT(L10,"mmm") -> Oct | F10: Ir. Pudjo Prihadi Santoso | G10: Jakarta Selatan | H10: =VLOOKUP(F10,'Counting Free'!$B:$F,4,0) -> 2 | I10: =VLOOKUP(F10,'Counting Kontrak'!B:E,4,0) -> 0 | J10: =VLOOKUP(F10,'Data Garansi'!$E:$I,5,0) -> Tidak | K10: =VLOOKUP(F10,'Tgl MC Free'!B:M,8,0) -> 46160 | L10: =VLOOKUP(F10,'Tgl Maintenance untuk Kontrak'!$D:$M,10,0) -> 46301 | M10: =TEXT(L10,"mmm") -> Oct
A11: 10 | B11: Domo Flex | C11: 21/0599 | D11: 44539 | E11: =TEXT(L11,"mmm") -> Jun | F11: PT. Dwipar Loka Ayu (Aswin) | G11: Jakarta Selatan | H11: =VLOOKUP(F11,'Counting Free'!$B:$F,4,0) -> 0 | I11: =VLOOKUP(F11,'Counting Kontrak'!B:E,4,0) -> 0 | J11: =VLOOKUP(F11,'Data Garansi'!$E:$I,5,0) -> Tidak | K11: =VLOOKUP(F11,'Tgl MC Free'!B:M,8,0) -> 46158 | L11: =VLOOKUP(F11,'Tgl Maintenance untuk Kontrak'!$D:$M,10,0) -> 46546 | M11: =TEXT(L11,"mmm") -> Jun
A12: 11 | B12: Domo Flex | C12: 21/0638 | D12: 44540 | E12: =TEXT(L12,"mmm") -> Apr | F12: Jenny Lie | G12: Medan | H12: =VLOOKUP(F12,'Counting Free'!$B:$F,4,0) -> 0 | I12: =VLOOKUP(F12,'Counting Kontrak'!B:E,4,0) -> 0 | J12: =VLOOKUP(F12,'Data Garansi'!$E:$I,5,0) -> Tidak | K12: =VLOOKUP(F12,'Tgl MC Free'!B:M,8,0) -> 46096 | L12: =VLOOKUP(F12,'Tgl Maintenance untuk Kontrak'!$D:$M,10,0) -> 46127 | M12: =TEXT(L12,"mmm") -> Apr
A13: 12 | B13: Domo Flex | C13: 21/0538 | D13: 44542 | E13: =TEXT(L13,"mmm") -> Oct | F13: Herry Gunawan | G13: Jawa Timur | H13: =VLOOKUP(F13,'Counting Free'!$B:$F,4,0) -> 2 | I13: =VLOOKUP(F13,'Counting Kontrak'!B:E,4,0) -> 0 | J13: =VLOOKUP(F13,'Data Garansi'!$E:$I,5,0) -> Tidak | K13: =VLOOKUP(F13,'Tgl MC Free'!B:M,8,0) -> 46136 | L13: =VLOOKUP(F13,'Tgl Maintenance untuk Kontrak'!$D:$M,10,0) -> 45956 | M13: =TEXT(L13,"mmm") -> Oct
A14: 13 | B14: Domo Flex | C14: 21/0570 | D14: 44551 | E14: =TEXT(L14,"mmm") -> May | F14: Drg. Melanie Hendriaty | G14: Jakarta Selatan | H14: =VLOOKUP(F14,'Counting Free'!$B:$F,4,0) -> 2 | I14: =VLOOKUP(F14,'Counting Kontrak'!B:E,4,0) -> 0 | J14: =VLOOKUP(F14,'Data Garansi'!$E:$I,5,0) -> Tidak | K14: =VLOOKUP(F14,'Tgl MC Free'!B:M,8,0) -> 46154 | L14: =VLOOKUP(F14,'Tgl Maintenance untuk Kontrak'!$D:$M,10,0) -> 46514 | M14: =TEXT(L14,"mmm") -> May
A15: 14 | B15: Domo Flex | C15: 21/0256 | D15: 44557 | E15: =TEXT(L15,"mmm") -> Mar | F15: Iskandar | G15: Jakarta Utara | H15: =VLOOKUP(F15,'Counting Free'!$B:$F,4,0) -> #N/A | I15: =VLOOKUP(F15,'Counting Kontrak'!B:E,4,0) -> #N/A | J15: =VLOOKUP(F15,'Data Garansi'!$E:$I,5,0) -> Tidak | K15: =VLOOKUP(F15,'Tgl MC Free'!B:M,8,0) -> 45900 | L15: =VLOOKUP(F15,'Tgl Maintenance untuk Kontrak'!$D:$M,10,0) -> 45720 | M15: =TEXT(L15,"mmm") -> Mar
A16: 15 | B16: Indomo Cabin | C16: 21/0740 | D16: 44571 | E16: =TEXT(L16,"mmm") -> Jul | F16: Thakurdas Pursani W | G16: Jakarta Utara | H16: =VLOOKUP(F16,'Counting Free'!$B:$F,4,0) -> 0 | I16: =VLOOKUP(F16,'Counting Kontrak'!B:E,4,0) -> 0 | J16: =VLOOKUP(F16,'Data Garansi'!$E:$I,5,0) -> Tidak | K16: =VLOOKUP(F16,'Tgl MC Free'!B:M,8,0) -> 46097 | L16: =VLOOKUP(F16,'Tgl Maintenance untuk Kontrak'!$D:$M,10,0) -> 46222 | M16: =TEXT(L16,"mmm") -> Jul
A17: 16 | B17: Indomo Cabin | C17: 21/0743 | D17: 44582 | F17: PT. Barnaby Kontruksi Sejahtera (Hilda) | G17: Jakarta Selatan | H17: =VLOOKUP(F17,'Counting Free'!$B:$F,4,0) -> 0 | I17: =VLOOKUP(F17,'Counting Kontrak'!B:E,4,0) -> 0 | J17: =VLOOKUP(F17,'Data Garansi'!$E:$I,5,0) -> Tidak | K17: =VLOOKUP(F17,'Tgl MC Free'!B:M,8,0) -> 45339 | L17: =VLOOKUP(F17,'Tgl Maintenance untuk Kontrak'!$D:$M,10,0) -> 45159 | M17: =TEXT(L17,"mmm") -> Aug
A18: 17 | B18: Domo Flex | C18: 21/0791 | D18: 44600 | E18: =TEXT(L18,"mmm") -> Dec | F18: Andy Indrajaya, ST | G18: Tangerang | H18: =VLOOKUP(F18,'Counting Free'!$B:$F,4,0) -> 0 | I18: =VLOOKUP(F18,'Counting Kontrak'!B:E,4,0) -> 0 | J18: =VLOOKUP(F18,'Data Garansi'!$E:$I,5,0) -> Tidak | K18: =VLOOKUP(F18,'Tgl MC Free'!B:M,8,0) -> 46172 | L18: =VLOOKUP(F18,'Tgl Maintenance untuk Kontrak'!$D:$M,10,0) -> 45992 | M18: =TEXT(L18,"mmm") -> Dec
A19: 18 | B19: Indomo Shaft | C19: 21/0618 | D19: 44601 | F19: Fahmuddin Edy Hadi, Yogjakarta | G19: Yogyakarta | H19: =VLOOKUP(F19,'Counting Free'!$B:$F,4,0) -> 2 | I19: =VLOOKUP(F19,'Counting Kontrak'!B:E,4,0) -> 0 | J19: =VLOOKUP(F19,'Data Garansi'!$E:$I,5,0) -> Tidak | K19: =VLOOKUP(F19,'Tgl MC Free'!B:M,8,0) -> 45482 | L19: =VLOOKUP(F19,'Tgl Maintenance untuk Kontrak'!$D:$M,10,0) -> 45302 | M19: =TEXT(L19,"mmm") -> Jan
A20: 19 | B20: Domo Flex | C20: 21/0879 | D20: 44602 | E20: =TEXT(L20,"mmm") -> Dec | F20: Hasan Dali | G20: Jakarta Barat | H20: =VLOOKUP(F20,'Counting Free'!$B:$F,4,0) -> 2 | I20: =VLOOKUP(F20,'Counting Kontrak'!B:E,4,0) -> 0 | J20: =VLOOKUP(F20,'Data Garansi'!$E:$I,5,0) -> Tidak | K20: =VLOOKUP(F20,'Tgl MC Free'!B:M,8,0) -> 46005 | L20: =VLOOKUP(F20,'Tgl Maintenance untuk Kontrak'!$D:$M,10,0) -> 45645 | M20: =TEXT(L20,"mmm") -> Dec
A21: 20 | B21: Domo Flex | C21: 21/0374 | D21: 44610 | E21: =TEXT(L21,"mmm") -> Jan | F21: Frans Andreas | G21: Bandung | H21: =VLOOKUP(F21,'Counting Free'!$B:$F,4,0) -> 1 | I21: =VLOOKUP(F21,'Counting Kontrak'!B:E,4,0) -> 0 | J21: =VLOOKUP(F21,'Data Garansi'!$E:$I,5,0) -> Tidak | K21: =VLOOKUP(F21,'Tgl MC Free'!B:M,8,0) -> 45856 | L21: =VLOOKUP(F21,'Tgl Maintenance untuk Kontrak'!$D:$M,10,0) -> 45676 | M21: =TEXT(L21,"mmm") -> Jan
A22: 21 | B22: Klasik | C22: 21/0916 | D22: 44622 | E22: =TEXT(L22,"mmm") -> Mar | F22: Natalina Surjani .S | G22: Jawa Timur | H22: =VLOOKUP(F22,'Counting Free'!$B:$F,4,0) -> 0 | I22: =VLOOKUP(F22,'Counting Kontrak'!B:E,4,0) -> 0 | J22: =VLOOKUP(F22,'Data Garansi'!$E:$I,5,0) -> Tidak | K22: =VLOOKUP(F22,'Tgl MC Free'!B:M,8,0) -> 46034 | L22: =VLOOKUP(F22,'Tgl Maintenance untuk Kontrak'!$D:$M,10,0) -> 46084 | M22: =TEXT(L22,"mmm") -> Mar
A23: 22 | B23: Klasik | C23: 21/0901 | D23: 44622 | E23: =TEXT(L23,"mmm") -> Feb | F23: Yayasan Karya Kasih Mandiri (Sigit) | G23: Jakarta Selatan | H23: =VLOOKUP(F23,'Counting Free'!$B:$F,4,0) -> 0 | I23: =VLOOKUP(F23,'Counting Kontrak'!B:E,4,0) -> 0 | J23: =VLOOKUP(F23,'Data Garansi'!$E:$I,5,0) -> Tidak | K23: =VLOOKUP(F23,'Tgl MC Free'!B:M,8,0) -> 46077 | L23: =VLOOKUP(F23,'Tgl Maintenance untuk Kontrak'!$D:$M,10,0) -> 46060 | M23: =TEXT(L23,"mmm") -> Feb
A24: 23 | B24: Domo Flex | C24: 21/0257 | D24: 44624 | E24: =TEXT(L24,"mmm") -> Mar | F24: Iskandar | G24: Jakarta Utara | H24: =VLOOKUP(F24,'Counting Free'!$B:$F,4,0) -> #N/A | I24: =VLOOKUP(F24,'Counting Kontrak'!B:E,4,0) -> #N/A | J24: =VLOOKUP(F24,'Data Garansi'!$E:$I,5,0) -> Tidak | K24: =VLOOKUP(F24,'Tgl MC Free'!B:M,8,0) -> 45900 | L24: =VLOOKUP(F24,'Tgl Maintenance untuk Kontrak'!$D:$M,10,0) -> 45720 | M24: =TEXT(L24,"mmm") -> Mar
A25: 24 | B25: Indomo Shaft | C25: 21/0534 | D25: 44628 | F25: Mirza Budiman Diran | G25: Jakarta Selatan | H25: =VLOOKUP(F25,'Counting Free'!$B:$F,4,0) -> 2 | I25: =VLOOKUP(F25,'Counting Kontrak'!B:E,4,0) -> 0 | J25: =VLOOKUP(F25,'Data Garansi'!$E:$I,5,0) -> Tidak | K25: =VLOOKUP(F25,'Tgl MC Free'!B:M,8,0) -> 45662 | L25: =VLOOKUP(F25,'Tgl Maintenance untuk Kontrak'!$D:$M,10,0) -> 46242
A26: 25 | B26: Domo Flex | C26: 21/0858 | D26: 44629 | F26: PT. Esa Pratama (Hafzah) | G26: Makassar | H26: =VLOOKUP(F26,'Counting Free'!$B:$F,4,0) -> 0 | I26: =VLOOKUP(F26,'Counting Kontrak'!B:E,4,0) -> 0 | J26: =VLOOKUP(F26,'Data Garansi'!$E:$I,5,0) -> Tidak | K26: =VLOOKUP(F26,'Tgl MC Free'!B:M,8,0) -> 45734 | L26: =VLOOKUP(F26,'Tgl Maintenance untuk Kontrak'!$D:$M,10,0) -> 45554
A27: 26 | B27: Pve 37 midio | C27: 192 | D27: 44635 | F27: PT Sumberdaya Indonesia (Andi Yusuf - Mangga)( nur graha bun) | G27: Jakarta Selatan | H27: =VLOOKUP(F27,'Counting Free'!$B:$F,4,0) -> #N/A | I27: =VLOOKUP(F27,'Counting Kontrak'!B:E,4,0) -> #N/A | J27: =VLOOKUP(F27,'Data Garansi'!$E:$I,5,0) -> #N/A | K27: =VLOOKUP(F27,'Tgl MC Free'!B:M,8,0) -> #N/A | L27: =VLOOKUP(F27,'Tgl Maintenance untuk Kontrak'!$D:$M,10,0) -> 46163
A28: 27 | B28: Indomo Cabin | C28: 21/1066 | D28: 44639 | E28: =TEXT(L28,"mmm") -> Aug | F28: PT. Semesta Andesit Perkasa (Budi) - PT. Vicindo Jaya Makmur | G28: Jakarta Utara | H28: =VLOOKUP(F28,'Counting Free'!$B:$F,4,0) -> 0 | I28: =VLOOKUP(F28,'Counting Kontrak'!B:E,4,0) -> 0 | J28: =VLOOKUP(F28,'Data Garansi'!$E:$I,5,0) -> Tidak | K28: =VLOOKUP(F28,'Tgl MC Free'!B:M,8,0) -> 46160 | L28: =VLOOKUP(F28,'Tgl Maintenance untuk Kontrak'!$D:$M,10,0) -> 46235 | M28: =TEXT(L28,"mmm") -> Aug
A29: 28 | B29: Domo Flex | C29: 21/0903 | D29: 44644 | E29: =TEXT(L29,"mmm") -> Jun | F29: Yayasan Perkembangan Anak Indonesia | G29: Jakarta Selatan | H29: =VLOOKUP(F29,'Counting Free'!$B:$F,4,0) -> 0 | I29: =VLOOKUP(F29,'Counting Kontrak'!B:E,4,0) -> 0 | J29: =VLOOKUP(F29,'Data Garansi'!$E:$I,5,0) -> Tidak | K29: =VLOOKUP(F29,'Tgl MC Free'!B:M,8,0) -> 46192 | L29: =VLOOKUP(F29,'Tgl Maintenance untuk Kontrak'!$D:$M,10,0) -> 46545 | M29: =TEXT(L29,"mmm") -> Jun
A30: 29 | B30: Domo Flex | C30: 21/1081 | D30: 44653 | F30: Abednego Wibowo (Hartono) | G30: Jakarta Utara | H30: =VLOOKUP(F30,'Counting Free'!$B:$F,4,0) -> 0 | I30: =VLOOKUP(F30,'Counting Kontrak'!B:E,4,0) -> 0 | J30: =VLOOKUP(F30,'Data Garansi'!$E:$I,5,0) -> Tidak | K30: =VLOOKUP(F30,'Tgl MC Free'!B:M,8,0) -> 360 | L30: =VLOOKUP(F30,'Tgl Maintenance untuk Kontrak'!$D:$M,10,0) -> 46072
A31: 30 | B31: Klasik | C31: 21/0994 | D31: 44656 | E31: =TEXT(L31,"mmm") -> Aug | F31: M. Dodiek Tas'an Wartono | G31: Jawa Tengah | H31: =VLOOKUP(F31,'Counting Free'!$B:$F,4,0) -> 0 | I31: =VLOOKUP(F31,'Counting Kontrak'!B:E,4,0) -> 0 | J31: =VLOOKUP(F31,'Data Garansi'!$E:$I,5,0) -> Tidak | K31: =VLOOKUP(F31,'Tgl MC Free'!B:M,8,0) -> 46068 | L31: =VLOOKUP(F31,'Tgl Maintenance untuk Kontrak'!$D:$M,10,0) -> 45888 | M31: =TEXT(L31,"mmm") -> Aug
A32: 31 | B32: Indomo Cabin | C32: 21/0621 | D32: 44659 | F32: Dr. Ketut Ananda W. Sp. OG (Klinik Ananda, Sumba) | G32: NTT | H32: =VLOOKUP(F32,'Counting Free'!$B:$F,4,0) -> 0 | I32: =VLOOKUP(F32,'Counting Kontrak'!B:E,4,0) -> 0 | J32: =VLOOKUP(F32,'Data Garansi'!$E:$I,5,0) -> Tidak | K32: =VLOOKUP(F32,'Tgl MC Free'!B:M,8,0) -> 360 | L32: =VLOOKUP(F32,'Tgl Maintenance untuk Kontrak'!$D:$M,10,0) -> 180
A33: 32 | B33: Domo Flex 2 | C33: 21/0922 | D33: 44667 | F33: PT. Mitra Niaga Nusatama (Jelly) | G33: Jakarta Utara | H33: =VLOOKUP(F33,'Counting Free'!$B:$F,4,0) -> 0 | I33: =VLOOKUP(F33,'Counting Kontrak'!B:E,4,0) -> 0 | J33: =VLOOKUP(F33,'Data Garansi'!$E:$I,5,0) -> Tidak | K33: =VLOOKUP(F33,'Tgl MC Free'!B:M,8,0) -> 360 | L33: =VLOOKUP(F33,'Tgl Maintenance untuk Kontrak'!$D:$M,10,0) -> 46287
A34: 33 | B34: Pve 37 midio | C34: 191 | D34: 44668 | E34: =TEXT(L34,"mmm") -> Oct | F34: Rajulur Rakhman | G34: Jakarta Timur | H34: =VLOOKUP(F34,'Counting Free'!$B:$F,4,0) -> 0 | I34: =VLOOKUP(F34,'Counting Kontrak'!B:E,4,0) -> 0 | J34: =VLOOKUP(F34,'Data Garansi'!$E:$I,5,0) -> Tidak | K34: =VLOOKUP(F34,'Tgl MC Free'!B:M,8,0) -> 46125 | L34: =VLOOKUP(F34,'Tgl Maintenance untuk Kontrak'!$D:$M,10,0) -> 45945 | M34: =TEXT(L34,"mmm") -> Oct
A35: 34 | B35: Domo Flex | C35: 21/0857 | D35: 44669 | F35: PT. PT Duta Raya Cipta (Gulshan) | G35: Puncak | H35: =VLOOKUP(F35,'Counting Free'!$B:$F,4,0) -> 0 | I35: =VLOOKUP(F35,'Counting Kontrak'!B:E,4,0) -> 0 | J35: =VLOOKUP(F35,'Data Garansi'!$E:$I,5,0) -> Tidak | K35: =VLOOKUP(F35,'Tgl MC Free'!B:M,8,0) -> 45589 | L35: =VLOOKUP(F35,'Tgl Maintenance untuk Kontrak'!$D:$M,10,0) -> 46063
A36: 35 | B36: Domo Flex | C36: 21/0877 | D36: 44671 | E36: =TEXT(L36,"mmm") -> May | F36: PT. Multilabindo Wahana (Hidayat) | G36: Jakarta Timur | H36: =VLOOKUP(F36,'Counting Free'!$B:$F,4,0) -> 0 | I36: =VLOOKUP(F36,'Counting Kontrak'!B:E,4,0) -> 0 | J36: =VLOOKUP(F36,'Data Garansi'!$E:$I,5,0) -> Tidak | K36: =VLOOKUP(F36,'Tgl MC Free'!B:M,8,0) -> 45982 | L36: =VLOOKUP(F36,'Tgl Maintenance untuk Kontrak'!$D:$M,10,0) -> 45802 | M36: =TEXT(L36,"mmm") -> May
A37: 36 | B37: Pve 37 midio | C37: 188 | D37: 44674 | E37: =TEXT(L37,"mmm") -> Mar | F37: Linda Irawati, Surabaya | G37: Jawa Timur | H37: =VLOOKUP(F37,'Counting Free'!$B:$F,4,0) -> 0 | I37: =VLOOKUP(F37,'Counting Kontrak'!B:E,4,0) -> 0 | J37: =VLOOKUP(F37,'Data Garansi'!$E:$I,5,0) -> Tidak | K37: =VLOOKUP(F37,'Tgl MC Free'!B:M,8,0) -> 46011 | L37: =VLOOKUP(F37,'Tgl Maintenance untuk Kontrak'!$D:$M,10,0) -> 46097 | M37: =TEXT(L37,"mmm") -> Mar
A38: 37 | B38: Klasik | C38: 21/1068 | D38: 44679 | F38: Linda Tjahja (Rivai) | G38: Jakarta Utara | H38: =VLOOKUP(F38,'Counting Free'!$B:$F,4,0) -> 0 | I38: =VLOOKUP(F38,'Counting Kontrak'!B:E,4,0) -> 0 | J38: =VLOOKUP(F38,'Data Garansi'!$E:$I,5,0) -> Tidak | K38: =VLOOKUP(F38,'Tgl MC Free'!B:M,8,0) -> 45726 | L38: =VLOOKUP(F38,'Tgl Maintenance untuk Kontrak'!$D:$M,10,0) -> 45546
A39: 38 | B39: Indomo Shaft | C39: 21/0962 | D39: 44681 | E39: =TEXT(L39,"mmm") -> Feb | F39: PT. Dwi Tunggal Putra (Michael) | G39: Depok | H39: =VLOOKUP(F39,'Counting Free'!$B:$F,4,0) -> 0 | I39: =VLOOKUP(F39,'Counting Kontrak'!B:E,4,0) -> 0 | J39: =VLOOKUP(F39,'Data Garansi'!$E:$I,5,0) -> Tidak | K39: =VLOOKUP(F39,'Tgl MC Free'!B:M,8,0) -> 46243 | L39: =VLOOKUP(F39,'Tgl Maintenance untuk Kontrak'!$D:$M,10,0) -> 45698 | M39: =TEXT(L39,"mmm") -> Feb
A40: 39 | B40: Klasik | C40: 21/1147 | D40: 44681 | E40: =TEXT(L40,"mmm") -> May | F40: Djohan Surya Adinata | G40: Bandung | H40: =VLOOKUP(F40,'Counting Free'!$B:$F,4,0) -> 0 | I40: =VLOOKUP(F40,'Counting Kontrak'!B:E,4,0) -> 0 | J40: =VLOOKUP(F40,'Data Garansi'!$E:$I,5,0) -> Tidak | K40: =VLOOKUP(F40,'Tgl MC Free'!B:M,8,0) -> 46126 | L40: =VLOOKUP(F40,'Tgl Maintenance untuk Kontrak'!$D:$M,10,0) -> 46168 | M40: =TEXT(L40,"mmm") -> May
...

Sheet Main Data Kunjungan
A1: No | B1: Nama Cust | C1: Free Kunjungan | D1: Kontrak Maintenance | E1: Kunjungan Berjalan | F1: Sisa Kunjungan
A2: 1 | B2: Ir. H. Awan Hermawan Purwadinata MT, Bandung | C2: =SUMIF('Counting Free'!B:B,'Main Data Kunjungan'!B2,'Counting Kontrak'!E:E) -> 0 | D2: =SUMIF('Counting Kontrak'!$B:$B,'Main Data Kunjungan'!B2,'Counting Kontrak'!$C:$C) -> 0 | E2: =SUMIF('Counting Kontrak'!$F:$F,B2,'Counting Kontrak'!$G:$G) -> 0 | F2: =C2+D2-E2 -> 0
A3: 2 | B3: Syamsuardi Alpat (Sudirman) | C3: =SUMIF('Counting Free'!B:B,'Main Data Kunjungan'!B3,'Counting Kontrak'!E:E) -> 0 | D3: =SUMIF('Counting Kontrak'!$B:$B,'Main Data Kunjungan'!B3,'Counting Kontrak'!$C:$C) -> 0 | E3: =SUMIF('Counting Kontrak'!$F:$F,B3,'Counting Kontrak'!$G:$G) -> 0 | F3: =C3+D3-E3 -> 0
A4: 3 | B4: Hendra Dwi Kurniawan | C4: =SUMIF('Counting Free'!B:B,'Main Data Kunjungan'!B4,'Counting Kontrak'!E:E) -> 0 | D4: =SUMIF('Counting Kontrak'!$B:$B,'Main Data Kunjungan'!B4,'Counting Kontrak'!$C:$C) -> 0 | E4: =SUMIF('Counting Kontrak'!$F:$F,B4,'Counting Kontrak'!$G:$G) -> 0 | F4: =C4+D4-E4 -> 0
A5: 4 | B5: CV Jawa Indah (Ibu Yuli), Samarinda, Kal-Tim | C5: =SUMIF('Counting Free'!B:B,'Main Data Kunjungan'!B5,'Counting Kontrak'!E:E) -> 0 | D5: =SUMIF('Counting Kontrak'!$B:$B,'Main Data Kunjungan'!B5,'Counting Kontrak'!$C:$C) -> 0 | E5: =SUMIF('Counting Kontrak'!$F:$F,B5,'Counting Kontrak'!$G:$G) -> 0 | F5: =C5+D5-E5 -> 0
A6: 5 | B6: PT. Yolita Plasinto Pratama ( Ida) | C6: =SUMIF('Counting Free'!B:B,'Main Data Kunjungan'!B6,'Counting Free'!F:F) -> 0 | D6: =SUMIF('Counting Kontrak'!$B:$B,'Main Data Kunjungan'!B6,'Counting Kontrak'!$C:$C) -> 14 | E6: =SUMIF('Counting Kontrak'!$F:$F,B6,'Counting Kontrak'!$G:$G) -> 1 | F6: =C6+D6-E6 -> 13
A7: 6 | B7: CV Pije Peter Cheryl (Andi) | C7: =SUMIF('Counting Free'!B:B,'Main Data Kunjungan'!B7,'Counting Kontrak'!E:E) -> 0 | D7: =SUMIF('Counting Kontrak'!$B:$B,'Main Data Kunjungan'!B7,'Counting Kontrak'!$C:$C) -> 0 | E7: =SUMIF('Counting Kontrak'!$F:$F,B7,'Counting Kontrak'!$G:$G) -> 0 | F7: =C7+D7-E7 -> 0
A8: 7 | B8: Esther Indrawati | C8: =SUMIF('Counting Free'!B:B,'Main Data Kunjungan'!B8,'Counting Kontrak'!E:E) -> 0 | D8: =SUMIF('Counting Kontrak'!$B:$B,'Main Data Kunjungan'!B8,'Counting Kontrak'!$C:$C) -> 0 | E8: =SUMIF('Counting Kontrak'!$F:$F,B8,'Counting Kontrak'!$G:$G) -> 0 | F8: =C8+D8-E8 -> 0
A9: 8 | B9: PT. Bertie Sukses Makmur (Andi) | C9: =SUMIF('Counting Free'!B:B,'Main Data Kunjungan'!B9,'Counting Kontrak'!E:E) -> 0 | D9: =SUMIF('Counting Kontrak'!$B:$B,'Main Data Kunjungan'!B9,'Counting Kontrak'!$C:$C) -> 0 | E9: =SUMIF('Counting Kontrak'!$F:$F,B9,'Counting Kontrak'!$G:$G) -> 0 | F9: =C9+D9-E9 -> 0
A10: 9 | B10: Ir. Pudjo Prihadi Santoso | C10: =SUMIF('Counting Free'!B:B,'Main Data Kunjungan'!B10,'Counting Kontrak'!E:E) -> 0 | D10: =SUMIF('Counting Kontrak'!$B:$B,'Main Data Kunjungan'!B10,'Counting Kontrak'!$C:$C) -> 0 | E10: =SUMIF('Counting Kontrak'!$F:$F,B10,'Counting Kontrak'!$G:$G) -> 0 | F10: =C10+D10-E10 -> 0
A11: 10 | B11: PT. Dwipar Loka Ayu (Aswin) | C11: =SUMIF('Counting Free'!B:B,'Main Data Kunjungan'!B11,'Counting Kontrak'!E:E) -> 0 | D11: =SUMIF('Counting Kontrak'!$B:$B,'Main Data Kunjungan'!B11,'Counting Kontrak'!$C:$C) -> 0 | E11: =SUMIF('Counting Kontrak'!$F:$F,B11,'Counting Kontrak'!$G:$G) -> 0 | F11: =C11+D11-E11 -> 0
A12: 11 | B12: Jenny Lie | C12: =SUMIF('Counting Free'!B:B,'Main Data Kunjungan'!B12,'Counting Kontrak'!E:E) -> 0 | D12: =SUMIF('Counting Kontrak'!$B:$B,'Main Data Kunjungan'!B12,'Counting Kontrak'!$C:$C) -> 0 | E12: =SUMIF('Counting Kontrak'!$F:$F,B12,'Counting Kontrak'!$G:$G) -> 0 | F12: =C12+D12-E12 -> 0
A13: 12 | B13: Herry Gunawan | C13: =SUMIF('Counting Free'!B:B,'Main Data Kunjungan'!B13,'Counting Kontrak'!E:E) -> 0 | D13: =SUMIF('Counting Kontrak'!$B:$B,'Main Data Kunjungan'!B13,'Counting Kontrak'!$C:$C) -> 0 | E13: =SUMIF('Counting Kontrak'!$F:$F,B13,'Counting Kontrak'!$G:$G) -> 0 | F13: =C13+D13-E13 -> 0
A14: 13 | B14: Drg. Melanie Hendriaty | C14: =SUMIF('Counting Free'!B:B,'Main Data Kunjungan'!B14,'Counting Kontrak'!E:E) -> 0 | D14: =SUMIF('Counting Kontrak'!$B:$B,'Main Data Kunjungan'!B14,'Counting Kontrak'!$C:$C) -> 0 | E14: =SUMIF('Counting Kontrak'!$F:$F,B14,'Counting Kontrak'!$G:$G) -> 0 | F14: =C14+D14-E14 -> 0
A15: 14 | B15: Iskandar | C15: =SUMIF('Counting Free'!B:B,'Main Data Kunjungan'!B15,'Counting Kontrak'!E:E) -> 0 | D15: =SUMIF('Counting Kontrak'!$B:$B,'Main Data Kunjungan'!B15,'Counting Kontrak'!$C:$C) -> 0 | E15: =SUMIF('Counting Kontrak'!$F:$F,B15,'Counting Kontrak'!$G:$G) -> 0 | F15: =C15+D15-E15 -> 0
A16: 15 | B16: Thakurdas Pursani W | C16: =SUMIF('Counting Free'!B:B,'Main Data Kunjungan'!B16,'Counting Kontrak'!E:E) -> 0 | D16: =SUMIF('Counting Kontrak'!$B:$B,'Main Data Kunjungan'!B16,'Counting Kontrak'!$C:$C) -> 0 | E16: =SUMIF('Counting Kontrak'!$F:$F,B16,'Counting Kontrak'!$G:$G) -> 0 | F16: =C16+D16-E16 -> 0
A17: 16 | B17: PT. Barnaby Kontruksi Sejahtera (Hilda) | C17: =SUMIF('Counting Free'!B:B,'Main Data Kunjungan'!B17,'Counting Kontrak'!E:E) -> 0 | D17: =SUMIF('Counting Kontrak'!$B:$B,'Main Data Kunjungan'!B17,'Counting Kontrak'!$C:$C) -> 0 | E17: =SUMIF('Counting Kontrak'!$F:$F,B17,'Counting Kontrak'!$G:$G) -> 0 | F17: =C17+D17-E17 -> 0
A18: 17 | B18: Andy Indrajaya, ST | C18: =SUMIF('Counting Free'!B:B,'Main Data Kunjungan'!B18,'Counting Kontrak'!E:E) -> 0 | D18: =SUMIF('Counting Kontrak'!$B:$B,'Main Data Kunjungan'!B18,'Counting Kontrak'!$C:$C) -> 0 | E18: =SUMIF('Counting Kontrak'!$F:$F,B18,'Counting Kontrak'!$G:$G) -> 0 | F18: =C18+D18-E18 -> 0
... A322: 321 | B322: Stefanus Yulianto (Evan Malang) | C322: =SUMIF('Counting Free'!B:B,'Main Data Kunjungan'!B322,'Counting Kontrak'!E:E) -> 0 | D322: =SUMIF('Counting Kontrak'!$B:$B,'Main Data Kunjungan'!B322,'Counting Kontrak'!$C:$C) -> 0 | E322: =SUMIF('Counting Kontrak'!$F:$F,B322,'Counting Kontrak'!$G:$G) -> 0 | F322: =C322+D322-E322 -> 0
A323: 322 | B323: Joseph utamin (Vera) | C323: =SUMIF('Counting Free'!B:B,'Main Data Kunjungan'!B323,'Counting Kontrak'!E:E) -> 0
A324: 323 | B324: Janne Idris | C324: =SUMIF('Counting Free'!B:B,'Main Data Kunjungan'!B324,'Counting Kontrak'!E:E) -> 0
A325: 324 | B325: Robin Zulkarnain ( robin sentul ) | C325: =SUMIF('Counting Free'!B:B,'Main Data Kunjungan'!B325,'Counting Kontrak'!E:E) -> 0
A326: 325 | B326: Hendra Suwardi | C326: =SUMIF('Counting Free'!B:B,'Main Data Kunjungan'!B326,'Counting Kontrak'!E:E) -> 0
A327: 326 | B327: Subagia Handaja | C327: =SUMIF('Counting Free'!B:B,'Main Data Kunjungan'!B327,'Counting Kontrak'!E:E) -> 0
A328: 327 | B328: Martin Budiman | C328: =SUMIF('Counting Free'!B:B,'Main Data Kunjungan'!B328,'Counting Kontrak'!E:E) -> 0
A329: 328 | B329: Etty Totong | C329: =SUMIF('Counting Free'!B:B,'Main Data Kunjungan'!B329,'Counting Kontrak'!E:E) -> 0
A330: 329 | B330: Fery Godzali | C330: =SUMIF('Counting Free'!B:B,'Main Data Kunjungan'!B330,'Counting Kontrak'!E:E) -> 0
A331: 330 | B331: Charly alam sutera | C331: =SUMIF('Counting Free'!B:B,'Main Data Kunjungan'!B331,'Counting Kontrak'!E:E) -> 0
A332: 331 | B332: Oen Malang | C332: =SUMIF('Counting Free'!B:B,'Main Data Kunjungan'!B332,'Counting Kontrak'!E:E) -> 0
A333: 332 | B333: PT Bintan lagoon resort | C333: =SUMIF('Counting Free'!B:B,'Main Data Kunjungan'!B333,'Counting Kontrak'!E:E) -> 0
A334: 333 | B334: Budhi Bekasi | C334: =SUMIF('Counting Free'!B:B,'Main Data Kunjungan'!B334,'Counting Kontrak'!E:E) -> 0
... A356: 355 | B356: Azis | C356: =SUMIF('Counting Free'!B:B,'Main Data Kunjungan'!B356,'Counting Kontrak'!E:E) -> 0

Sheet Tgl Maintenance untuk Kontrak
A1: No | B1: Jenis Lift | C1: Code Lift | D1: Nama Cust | E1: Alamat | F1: Area | G1: Tgl Maintenance 1 | H1: Status | I1: Tgl Maintenance Ke - 2 | J1: Status | K1: Tgl Maintenance ke -3 | L1: Status | M1: Maintenance Berjalan | O1: 180 | P1: 120
A2: 311 | B2: Stairlift | C2: UP-004959 | D2: Febby | E2: #N/A | F2: Jakarta Selatan | G2: 45783 | H2: done | I2: 45923 | J2: Done | K2: =I2+$O$1 -> 46103 | M2: =IF(H2="Done",IF(J2="Done",IF(L2="Done","-",K2),I2),G2) -> 46103
A3: 309 | B3: Swift Lite | D3: Grace Sintjie Soegiarto | E3: Jl. Mutiara I no. 43, Permata Hijau, Jakarta Selatan | F3: Jakarta Selatan | G3: 45782 | H3: done | I3: 45939 | J3: Service | K3: 46126 | L3: Sevice | M3: =IF(H3="Done",IF(J3="Done",IF(L3="Done","-",K3),I3),G3) -> 45939
A4: 314 | B4: Swift Lite | C4: SW113048 | D4: Firman Rusli | E4: #N/A | F4: Jakarta Barat | G4: 45800 | H4: done | I4: 45946 | J4: Done | K4: =I4+$O$1 -> 46126 | M4: =IF(H4="Done",IF(J4="Done",IF(L4="Done","-",K4),I4),G4) -> 46126
A5: 315 | B5: Swift Pro | C5: SW112895 | D5: DRS. Ricky Irawan | E5: Riverpark GF.1 No.16, Bintaro Jaya Sektor 8, Pondok Jaya, Pondok Aren, Tangerang Selatan | F5: Jakarta Selatan | G5: 45801 | H5: done | I5: 45968 | J5: Done | K5: =I5+$O$1 -> 46148 | M5: =IF(H5="Done",IF(J5="Done",IF(L5="Done","-",K5),I5),G5) -> 46148
A6: 301 | B6: Swift Lite | C6: SW112686 | D6: Burhanudin (Ebdesk Teknologi- Muhammad Iqbal) | E6: #N/A | F6: Jakarta Selatan | G6: 45737 | H6: done | I6: 45901 | J6: Done | K6: =I6+$O$1 -> 46081 | M6: =IF(H6="Done",IF(J6="Done",IF(L6="Done","-",K6),I6),G6) -> 46081
A7: 318 | B7: Swift Pro | C7: SW112680 | D7: PT. PRIAMANAYA ENERGI (Rasyad) | E7: #N/A | F7: Jakarta Pusat | G7: 45805 | H7: done | I7: 45958 | J7: main 1 | K7: =I7+$O$1 -> 46138 | M7: =IF(H7="Done",IF(J7="Done",IF(L7="Done","-",K7),I7),G7) -> 45958
A8: 296 | B8: Swift Lite | C8: SW112370 | D8: Clara Fransisca Darniaty | E8: #N/A | F8: Sentul | G8: 45715 | H8: done | I8: 45903 | J8: Done | K8: =I8+$O$1 -> 46083 | M8: =IF(H8="Done",IF(J8="Done",IF(L8="Done","-",K8),I8),G8) -> 46083
A9: 299 | B9: Swift Pro | C9: SW112229 | D9: Jacobus Irawan | E9: #N/A | F9: Jakarta Selatan | G9: 45733 | H9: done | I9: 45931 | J9: Done | K9: =I9+$O$1 -> 46111 | M9: =IF(H9="Done",IF(J9="Done",IF(L9="Done","-",K9),I9),G9) -> 46111
A10: 289 | B10: Swift Lite | C10: SW111988 | D10: CV Ozone Friendly (Johansen Ngian) | E10: Taman Resort Medieterania 29/3 PIK | F10: Jakarta Utara | G10: 45862 | H10: done | I10: 46032 | J10: Done | K10: =I10+$O$1 -> 46212 | M10: =IF(H10="Done",IF(J10="Done",IF(L10="Done","-",K10),I10),G10) -> 46212
A11: 286 | B11: Swift Lite | C11: SW111717 | D11: Indra Usmansjah Bakrie | E11: Jl. Mega Kuningan Timur No.88 Kuningan, Jaksel | F11: Jakarta Selatan | G11: 45832 | H11: done | I11: 45989 | J11: Done | K11: =I11+$O$1 -> 46169 | M11: =IF(H11="Done",IF(J11="Done",IF(L11="Done","-",K11),I11),G11) -> 46169
A12: 272 | B12: Swift Lite | C12: SW111445 | D12: Goey Sioe Giok (Bpk Astan) Sunter | E12: Jl. Agung Perkasa XII Blok J 13 No 18 | F12: Jakarta Utara | G12: 45840 | H12: done | I12: 46093 | J12: Done | K12: =I12+$O$1 -> 46273 | M12: =IF(H12="Done",IF(J12="Done",IF(L12="Done","-",K12),I12),G12) -> 46273
A13: 295 | B13: Swift Pro | C13: SW111197 | D13: Hargono, Drs-Banjarmasin | E13: #N/A | F13: kalimantan tengah | G13: 45715 | H13: done | I13: 45960 | J13: Done | K13: =I13+$O$1 -> 46140 | M13: =IF(H13="Done",IF(J13="Done",IF(L13="Done","-",K13),I13),G13) -> 46140
A14: 306 | B14: Swift Lite | C14: SW111110 | D14: Lo Herry | E14: Jl. Kintamani 2 No. 30 RT 003 RW 007, Kelapa Gading Barat, Jakarta | F14: Jakarta Utara | G14: 45762 | H14: done | I14: 45888 | J14: Done | K14: =I14+$O$1 -> 46068 | M14: =IF(H14="Done",IF(J14="Done",IF(L14="Done","-",K14),I14),G14) -> 46068
A15: 280 | B15: Swift Pro | C15: SW111072 | D15: Janni BSD | E15: Jl. Tiara Utara II No.32, Cihuni, Kec. Pagedangan, Kabupaten Tangerang, Banten 15332 | F15: Tangerang | G15: 45842 | H15: Done | I15: 45980 | J15: Done | K15: =I15+$O$1 -> 46160 | M15: =IF(H15="Done",IF(J15="Done",IF(L15="Done","-",K15),I15),G15) -> 46160
A16: 278 | B16: Swift Lite | C16: SW110975 | D16: Yulianah Yulianah - Julius | E16: Cluster Mozart Selatan V No. 01 Gading Serpong | F16: Tangerang | G16: 45811 | H16: done | I16: 45896 | J16: Done | K16: =I16+$O$1 -> 46076 | M16: =IF(H16="Done",IF(J16="Done",IF(L16="Done","-",K16),I16),G16) -> 46076
A17: 287 | B17: Swift Lite | C17: SW110925 | D17: Elsye Augustina Lie | E17: Wisata Bukit Mas I/ A 17 Kel lidah wetan kec lakarsantri Surabaya | F17: Surabaya | G17: 45807 | H17: done | I17: 45917 | J17: service 9/1 | K17: 46134 | L17: Done | M17: =IF(H17="Done",IF(J17="Done",IF(L17="Done","-",K17),I17),G17) -> 45917
A18: 285 | B18: Swift Lite | C18: SW110912 | D18: Tutiawati Subagio | E18: Jl Taman Ratu Indaha Block CC 1 No.18, Jakarta Barat | F18: Jakarta Barat | G18: 45794 | H18: done | I18: 45960 | J18: Done | K18: =I18+$O$1 -> 46140 | M18: =IF(H18="Done",IF(J18="Done",IF(L18="Done","-",K18),I18),G18) -> 46140
A19: 298 | B19: Swift Lite | C19: SW110460 | D19: Esmaldiansyah | E19: Jl. Niaga Hijau II No. 32 Jakarta Selatan | F19: Jakarta Selatan | G19: 45733 | H19: done | I19: 45887 | J19: done | K19: =I19+$O$1 -> 46067 | M19: =IF(H19="Done",IF(J19="Done",IF(L19="Done","-",K19),I19),G19) -> 46067
A20: 282 | B20: Swift Lite | C20: SW110357 | D20: Priska | E20: Jl. Pluit Putri I No.11, Jakarta Utara | F20: Jakarta Utara | G20: 45754 | H20: done | I20: 45941 | J20: Done | K20: =I20+$O$1 -> 46121 | M20: =IF(H20="Done",IF(J20="Done",IF(L20="Done","-",K20),I20),G20) -> 46121
A21: 265 | B21: Swift Pro | C21: SW110356 | D21: PT. Hatsonsurya Electric (Hariyanto)-Surabaya | E21: #N/A | F21: Surabaya | G21: 45904 | H21: Done | I21: =G21+$O$1 -> 46084 | K21: =I21+$O$1 -> 46264 | M21: =IF(H21="Done",IF(J21="Done",IF(L21="Done","-",K21),I21),G21) -> 46084
A22: 274 | B22: Swift Lite | C22: SW110337 | D22: PT. Karya Akbar Mandiri (Anggia) | E22: Jl. Darmawangsa Raya No. 8 Jakarta Selatan. Titik map: Blume Orchid (Rumah Sebrangny) | F22: Jakarta Selatan | G22: 45829 | H22: done | I22: 45980 | J22: Done | K22: =I22+$O$1 -> 46160 | M22: =IF(H22="Done",IF(J22="Done",IF(L22="Done","-",K22),I22),G22) -> 46160
A23: 307 | B23: Swift Lite | C23: SW110266 | D23: Linas - Bandung | E23: Jl. Gajah no.18, Bandung | F23: Bandung | G23: 45766 | H23: done | I23: 45987 | J23: Done | K23: =I23+$O$1 -> 46167 | M23: =IF(H23="Done",IF(J23="Done",IF(L23="Done","-",K23),I23),G23) -> 46167
A24: 271 | B24: Swift Lite | C24: SW109596 | D24: PT. Gagah Putera Satria-Dharma | E24: Jl Wijaya Kusuma No.9, Jatipulo, Palmerah, Jakarta Barat | F24: Jakarta Barat | G24: 45817 | H24: done | I24: 45989 | J24: Done | K24: =I24+$O$1 -> 46169 | M24: =IF(H24="Done",IF(J24="Done",IF(L24="Done","-",K24),I24),G24) -> 46169
A25: 273 | B25: Swift Lite | C25: SW109439 | D25: PT. Nindya Karya (IKN) | E25: 0 | F25: IKN | G25: 45813 | H25: done | I25: 46034 | J25: Done | K25: =I25+$O$1 -> 46214 | M25: =IF(H25="Done",IF(J25="Done",IF(L25="Done","-",K25),I25),G25) -> 46214
A26: 252 | B26: Swift Lite | C26: SW109291 | D26: Dr. Eddy Widodo | E26: Jl. Biak No.28, RT.3/RW.6, Cideng, Kecamatan Gambir, Kota Jakarta Pusat, Daerah Khusus Ibukota Jakarta 10150 | F26: Jakarta Pusat | G26: 45848 | H26: done | I26: 46029 | J26: Done | K26: =I26+$O$1 -> 46209 | M26: =IF(H26="Done",IF(J26="Done",IF(L26="Done","-",K26),I26),G26) -> 46209
A27: 267 | B27: Swift Pro | C27: SW109242 | D27: JUJUN TJAKRALAKSAN-Bandung | E27: Jl Setra Duta Blok N no.2 RT 002 RW 014, Parongpong, Bandung Barat | F27: Bandung | G27: 45826 | H27: done | I27: 45988 | J27: Done | K27: =I27+$O$1 -> 46168 | M27: =IF(H27="Done",IF(J27="Done",IF(L27="Done","-",K27),I27),G27) -> 46168
A28: 249 | B28: Swift Lite | C28: SW108858 | D28: H. Mahmud Fauzi Nasir-Masjid Nurul Amal | E28: Jl. Gama Setia Barat 1, Komplek Pelni Depok | F28: Depok | G28: 45805 | H28: Done | I28: 46363 | J28: Done | K28: =I28+$O$1 -> 46543 | M28: =IF(H28="Done",IF(J28="Done",IF(L28="Done","-",K28),I28),G28) -> 46543
A29: 246 | B29: Swift Lite | C29: SW108740 | D29: Yay Budi Siswa Mr. Pater R.B. Leonardus Evert Bambang Winandoko, SJ | E29: Jl Menteng Raya no.64 (Kolase Kanisius) | F29: Jakarta Pusat | G29: 45836 | H29: done | I29: 45989 | J29: kanisus | K29: =I29+$O$1 -> 46169 | M29: =IF(H29="Done",IF(J29="Done",IF(L29="Done","-",K29),I29),G29) -> 45989
A30: 251 | B30: Swift Lite | C30: SW108260 | D30: PT Hurama Anugerah Berjaya - Robin | E30: #N/A | F30: Jakarta Utara | G30: 45813 | H30: done | I30: =G30+$O$1 -> 45993 | J30: done | K30: =I30+$O$1 -> 46173 | M30: =IF(H30="Done",IF(J30="Done",IF(L30="Done","-",K30),I30),G30) -> 46173
A31: 233 | B31: Swift Pro | C31: SW108102 | D31: PT Pulau Intan (Yashinta Menteng) | E31: Jl. Pangeran Diponegoro, RT.15/RW.5, Menteng, Kec. Menteng, Kota Jakarta Pusat, Daerah Khusus Ibukota Jakarta 14240 | F31: Jakarta Pusat | G31: 45847 | H31: done | I31: 45966 | J31: Done | K31: =I31+$O$1 -> 46146 | M31: =IF(H31="Done",IF(J31="Done",IF(L31="Done","-",K31),I31),G31) -> 46146
A32: 237 | B32: Swift Lite | C32: SW108015 | D32: Tinus Thepadjaya | E32: Jl. Moti No. 1 RT 004 RW 005, Cideng, Gambir, Jakarta Pusat | F32: Jakarta Pusat | G32: 45800 | H32: done | I32: 45993 | J32: Done | K32: =I32+$O$1 -> 46173 | M32: =IF(H32="Done",IF(J32="Done",IF(L32="Done","-",K32),I32),G32) -> 46173
A33: 247 | B33: Swift Pro | C33: SW108002 | D33: PT Jaya Kusuma Sarana | E33: Taman Golf no 75, Lippo Karawaci | F33: Karawaci | G33: 45635 | H33: done | I33: 45890 | J33: done | K33: =I33+$O$1 -> 46070 | M33: =IF(H33="Done",IF(J33="Done",IF(L33="Done","-",K33),I33),G33) -> 46070
A34: 239 | B34: Swift Lite | C34: SW107327 | D34: KSO ADHI-CEC | E34: #N/A | F34: IKN | G34: 45813 | H34: Done | I34: 46034 | J34: Done | K34: =I34+$O$1 -> 46214 | M34: =IF(H34="Done",IF(J34="Done",IF(L34="Done","-",K34),I34),G34) -> 46214
A35: 264 | B35: Swift Pro | C35: SW107230 | D35: Sri Ayu Lestari | E35: Jalan Pramuka Komplek Green Pramuka No.1 , Banjarmasin | F35: Kalimantan Selatan | G35: 45810 | H35: done | I35: 46074 | J35: Done | K35: =I35+$O$1 -> 46254 | M35: =IF(H35="Done",IF(J35="Done",IF(L35="Done","-",K35),I35),G35) -> 46254
A36: 220 | B36: Swift Lite | C36: SW107100 | D36: Mr. Jorge Serrano-Timor Leste | E36: apostolic nunciature avenidad motael,lirio, vera cruz, dili, timor leste | F36: Timor Leste | I36: =G36+$O$1 -> 180 | K36: =I36+$O$1 -> 360 | M36: =IF(H36="Done",IF(J36="Done",IF(L36="Done","-",K36),I36),G36) -> 0
A37: 226 | B37: Swift Pro | C37: SW106823 | D37: PT Renata Global Supply | E37: Ruko Northridge business center blok B1 no.11, BSD, tangerang | F37: Tangerang | G37: 45831 | H37: done | I37: 45945 | J37: Done | K37: =I37+$O$1 -> 46125 | M37: =IF(H37="Done",IF(J37="Done",IF(L37="Done","-",K37),I37),G37) -> 46125
A38: 208 | B38: Swift Lite | C38: SW106708 | D38: Monica Pranata | E38: Vermont Parkland J2/5, BSD City,tangerang | F38: tangerang | G38: 45694 | H38: done | I38: 45891 | J38: Done | K38: =I38+$O$1 -> 46071 | M38: =IF(H38="Done",IF(J38="Done",IF(L38="Done","-",K38),I38),G38) -> 46071
A39: 195 | B39: Swift Pro | C39: SW106660 | D39: Prof Dr. Maya Devita Lokanata Sp D.V.E | E39: Jl Rajawali Selatan IV no.41 RT 006 rw 006, Gunung Sahari utara, Sawah Besar, Jakarta Pusat | F39: Jakarta Pusat | G39: 45831 | H39: done | I39: 45987 | J39: Done | K39: =I39+$O$1 -> 46167 | M39: =IF(H39="Done",IF(J39="Done",IF(L39="Done","-",K39),I39),G39) -> 46167
A40: 199 | B40: Swift Pro | C40: SW106057 | D40: PT Implementasi Teknologi Indonesia (Arief Sofian) | E40: Jl. Parpostel No.55 Jatiasih, Bekasi | F40: Bekasi | H40: sdh dkgi | I40: =G40+$O$1 -> 180 | K40: =I40+$O$1 -> 360 | M40: =IF(H40="Done",IF(J40="Done",IF(L40="Done","-",K40),I40),G40) -> 0
...

Sheet Data Garansi
A1: No | B1: Jenis Lift | C1: Code Lift | D1: Tgl BAST | E1: Nama Cust | F1: Masa Garansi ( Days ) | G1: Tgl Hari Ini | H1: Days From BAST | I1: Garansi atau Tidak | J1: Free Maintenance Sisa
A2: 1 | B2: Domo Flex | C2: 21/0670 | D2: 44201 | E2: Ir. H. Awan Hermawan Purwadinata MT, Bandung | F2: 365 | G2: =TODAY() -> 46150 | H2: =G2-D2 -> 1949 | I2: =IF(H2>F2,"Tidak","Garansi") -> Tidak
A3: 2 | B3: Galactic | C3: 21/0745 | D3: 44255 | E3: Syamsuardi Alpat (Sudirman) | F3: 365 | G3: =TODAY() -> 46150 | H3: =G3-D3 -> 1895 | I3: =IF(H3>F3,"Tidak","Garansi") -> Tidak
A4: 3 | B4: Domo Flex | C4: 21/0227 | D4: 44400 | E4: Hendra Dwi Kurniawan | F4: 365 | G4: =TODAY() -> 46150 | H4: =G4-D4 -> 1750 | I4: =IF(H4>F4,"Tidak","Garansi") -> Tidak
A5: 4 | B5: Indomo Shaft | C5: 21/0258 | D5: 44428 | E5: CV Jawa Indah (Ibu Yuli), Samarinda, Kal-Tim | F5: 365 | G5: =TODAY() -> 46150 | H5: =G5-D5 -> 1722 | I5: =IF(H5>F5,"Tidak","Garansi") -> Tidak
A6: 5 | B6: Pve 37 midio | C6: PVE | D6: 44435 | E6: PT. Yolita Plasinto Pratama ( Ida) | F6: 365 | G6: =TODAY() -> 46150 | H6: =G6-D6 -> 1715 | I6: =IF(H6>F6,"Tidak","Garansi") -> Tidak
A7: 6 | B7: Domo Flex | C7: 21/0455 | D7: 44474 | E7: CV Pije Peter Cheryl (Andi) | F7: 365 | G7: =TODAY() -> 46150 | H7: =G7-D7 -> 1676 | I7: =IF(H7>F7,"Tidak","Garansi") -> Tidak
A8: 7 | B8: Domo Flex | C8: 21/0542 | D8: 44490 | E8: Esther Indrawati | F8: 365 | G8: =TODAY() -> 46150 | H8: =G8-D8 -> 1660 | I8: =IF(H8>F8,"Tidak","Garansi") -> Tidak
A9: 8 | B9: Domo Flex | C9: 21/0375 | D9: 44517 | E9: PT. Bertie Sukses Makmur (Andi) | F9: 365 | G9: =TODAY() -> 46150 | H9: =G9-D9 -> 1633 | I9: =IF(H9>F9,"Tidak","Garansi") -> Tidak
A10: 9 | B10: Domo Flex | C10: 21/0676 | D10: 44525 | E10: Ir. Pudjo Prihadi Santoso | F10: 365 | G10: =TODAY() -> 46150 | H10: =G10-D10 -> 1625 | I10: =IF(H10>F10,"Tidak","Garansi") -> Tidak
A11: 10 | B11: Domo Flex | C11: 21/0599 | D11: 44539 | E11: PT. Dwipar Loka Ayu (Aswin) | F11: 365 | G11: =TODAY() -> 46150 | H11: =G11-D11 -> 1611 | I11: =IF(H11>F11,"Tidak","Garansi") -> Tidak
A12: 11 | B12: Domo Flex | C12: 21/0638 | D12: 44540 | E12: Jenny Lie | F12: 365 | G12: =TODAY() -> 46150 | H12: =G12-D12 -> 1610 | I12: =IF(H12>F12,"Tidak","Garansi") -> Tidak
A13: 12 | B13: Domo Flex | C13: 21/0538 | D13: 44542 | E13: Herry Gunawan | F13: 365 | G13: =TODAY() -> 46150 | H13: =G13-D13 -> 1608 | I13: =IF(H13>F13,"Tidak","Garansi") -> Tidak
... A26: 25 | B26: Domo Flex | C26: 21/0858 | D26: 44629 | E26: PT. Esa Pratama (Hafzah) | F26: 365 | G26: =TODAY() -> 46150 | H26: =G26-D26 -> 1521 | I26: =IF(H26>F26,"Tidak","Garansi") -> Tidak
A27: 26 | B27: Pve 37 midio | C27: 192 | D27: 44635 | E27: PT Sumberdaya Indonesia (Andi Yusuf - Mangga) | F27: 365 | G27: =TODAY() -> 46150 | H27: =G27-D27 -> 1515 | I27: =IF(H27>F27,"Tidak","Garansi") -> Tidak
A28: 27 | B28: Indomo Cabin | C28: 21/1066 | D28: 44639 | E28: PT. Semesta Andesit Perkasa (Budi) - PT. Vicindo Jaya Makmur | F28: 365 | G28: =TODAY() -> 46150 | H28: =G28-D28 -> 1511 | I28: =IF(H28>F28,"Tidak","Garansi") -> Tidak
A29: 28 | B29: Domo Flex | C29: 21/0903 | D29: 44644 | E29: Yayasan Perkembangan Anak Indonesia | F29: 365 | G29: =TODAY() -> 46150 | H29: =G29-D29 -> 1506 | I29: =IF(H29>F29,"Tidak","Garansi") -> Tidak
A30: 29 | B30: Domo Flex | C30: 21/1081 | D30: 44653 | E30: Abednego Wibowo (Hartono) | F30: 365 | G30: =TODAY() -> 46150 | H30: =G30-D30 -> 1497 | I30: =IF(H30>F30,"Tidak","Garansi") -> Tidak
A31: 30 | B31: Klasik | C31: 21/0994 | D31: 44656 | E31: M. Dodiek Tas'an Wartono | F31: 365 | G31: =TODAY() -> 46150 | H31: =G31-D31 -> 1494 | I31: =IF(H31>F31,"Tidak","Garansi") -> Tidak
A32: 31 | B32: Indomo Cabin | C32: 21/0621 | D32: 44659 | E32: Dr. Ketut Ananda W. Sp. OG (Klinik Ananda, Sumba) | F32: 365 | G32: =TODAY() -> 46150 | H32: =G32-D32 -> 1491 | I32: =IF(H32>F32,"Tidak","Garansi") -> Tidak
A33: 32 | B33: Domo Flex 2 | C33: 21/0922 | D33: 44667 | E33: PT. Mitra Niaga Nusatama (Jelly) | F33: 365 | G33: =TODAY() -> 46150 | H33: =G33-D33 -> 1483 | I33: =IF(H33>F33,"Tidak","Garansi") -> Tidak
A34: 33 | B34: Pve 37 midio | C34: 191 | D34: 44668 | E34: Rajulur Rakhman | F34: 365 | G34: =TODAY() -> 46150 | H34: =G34-D34 -> 1482 | I34: =IF(H34>F34,"Tidak","Garansi") -> Tidak
A35: 34 | B35: Domo Flex | C35: 21/0857 | D35: 44669 | E35: PT. PT Duta Raya Cipta (Gulshan) | F35: 365 | G35: =TODAY() -> 46150 | H35: =G35-D35 -> 1481 | I35: =IF(H35>F35,"Tidak","Garansi") -> Tidak
A36: 35 | B36: Domo Flex | C36: 21/0877 | D36: 44671 | E36: PT. Multilabindo Wahana (Hidayat) | F36: 365 | G36: =TODAY() -> 46150 | H36: =G36-D36 -> 1479 | I36: =IF(H36>F36,"Tidak","Garansi") -> Tidak
A37: 36 | B37: Pve 37 midio | C37: 188 | D37: 44674 | E37: Linda Irawati, Surabaya | F37: 365 | G37: =TODAY() -> 46150 | H37: =G37-D37 -> 1476 | I37: =IF(H37>F37,"Tidak","Garansi") -> Tidak
A38: 37 | B38: Klasik | C38: 21/1068 | D38: 44679 | E38: Linda Tjahja (Rivai) | F38: 365 | G38: =TODAY() -> 46150 | H38: =G38-D38 -> 1471 | I38: =IF(H38>F38,"Tidak","Garansi") -> Tidak
A39: 38 | B39: Indomo Shaft | C39: 21/0962 | D39: 44681 | E39: PT. Dwi Tunggal Putra (Michael) | F39: 365 | G39: =TODAY() -> 46150 | H39: =G39-D39 -> 1469 | I39: =IF(H39>F39,"Tidak","Garansi") -> Tidak
A40: 39 | B40: Klasik | C40: 21/1147 | D40: 44681 | E40: Djohan Surya Adinata | F40: 365 | G40: =TODAY() -> 46150 | H40: =G40-D40 -> 1469 | I40: =IF(H40>F40,"Tidak","Garansi") -> Tidak
A41: 40 | B41: Galactic | C41: 21/0973 | D41: 44710 | E41: Felix Claudius Djimin (Greysia/ PT Kreasi Bintang Anugerah) | F41: 365 | G41: =TODAY() -> 46150 | H41: =G41-D41 -> 1440 | I41: =IF(H41>F41,"Tidak","Garansi") -> Tidak
A42: 41 | B42: Domo Flex | C42: 21/0878 | D42: 44711 | E42: Monica Irmawati Koswara | F42: 365 | G42: =TODAY() -> 46150 | H42: =G42-D42 -> 1439 | I42: =IF(H42>F42,"Tidak","Garansi") -> Tidak
A43: 42 | B43: Klasik | C43: 21/1208 | D43: 44713 | E43: PT. Comfort Aire Aneka Teknik (Edy - Bintaro) | F43: 365 | G43: =TODAY() -> 46150 | H43: =G43-D43 -> 1437 | I43: =IF(H43>F43,"Tidak","Garansi") -> Tidak
A44: 43 | B44: Domo Flex | C44: 21/0885 | D44: 44722 | E44: Farida Anwari | F44: 365 | G44: =TODAY() -> 46150 | H44: =G44-D44 -> 1428 | I44: =IF(H44>F44,"Tidak","Garansi") -> Tidak
A45: 44 | B45: Galactic | C45: 21/0973 | D45: 44730 | E45: Jonatan Christie | F45: 365 | G45: =TODAY() -> 46150 | H45: =G45-D45 -> 1420 | I45: =IF(H45>F45,"Tidak","Garansi") -> Tidak
A46: 45 | B46: Domo Flex | C46: 21/1072 | D46: 44730 | E46: Ir. Tjahjono Tjandra | F46: 365 | G46: =TODAY() -> 46150 | H46: =G46-D46 -> 1420 | I46: =IF(H46>F46,"Tidak","Garansi") -> Tidak
A47: 46 | B47: Domo Flex | C47: 21/1135 | D47: 44734 | E47: Johan Suhalim | F47: 365 | G47: =TODAY() -> 46150 | H47: =G47-D47 -> 1416 | I47: =IF(H47>F47,"Tidak","Garansi") -> Tidak
A48: 47 | B48: Klasik | C48: 21/1067 | D48: 44740 | E48: Jessica Ronaldy Tjahja (Sumitra) | F48: 365 | G48: =TODAY() -> 46150 | H48: =G48-D48 -> 1410 | I48: =IF(H48>F48,"Tidak","Garansi") -> Tidak
A49: 48 | B49: Stairfit | C49: 21/1120 | D49: 44740 | E49: Taruna Wirano Lukman (Rully) | F49: 365 | G49: =TODAY() -> 46150 | H49: =G49-D49 -> 1410 | I49: =IF(H49>F49,"Tidak","Garansi") -> Tidak
... A60: 58 | B60: Indomo Cabin | C60: 21/0812 | D60: 44776 | E60: Jico Maradona | F60: 365 | G60: =TODAY() -> 46150 | H60: =G60-D60 -> 1374 | I60: =IF(H60>F60,"Tidak","Garansi") -> Tidak
A61: 59 | B61: Pve 37 midio | C61: 190 | D61: 44777 | E61: Sofian Atmadja Widjaja | F61: 365 | G61: =TODAY() -> 46150 | H61: =G61-D61 -> 1373 | I61: =IF(H61>F61,"Tidak","Garansi") -> Tidak
A62: 60 | B62: Pve 37 midio | C62: PVE | D62: 44781 | E62: Howard Kasima | F62: 365 | G62: =TODAY() -> 46150 | H62: =G62-D62 -> 1369 | I62: =IF(H62>F62,"Tidak","Garansi") -> Tidak
...

Sheet Counting Free
A1: No | B1: Nama Cust | D1: Total Free Awal | E1: Total Kunjungan | F1: Sisa Free | G1: Nama Cust | H1: Total Kunjungan | I1: Kunjungan Ke - | J1: Visit Date | K1: Status | L1: Tech | M1: Report | N1: Note
A2: 1 | B2: Ir. H. Awan Hermawan Purwadinata MT, Bandung | C2: 21/0670 | D2: 2 | E2: =SUMIF($G:$G,B2,$H:$H) -> 0 | F2: =D2-E2 -> 2 | G2: PT. Yolita Plasinto Pratama ( Ida) | H2: 1 | I2: 1 | J2: 45054 | K2: Done | L2: Rifaldi | M2: Ganti Battery
A3: 2 | B3: Syamsuardi Alpat (Sudirman) | C3: 21/0745 | D3: 2 | E3: =SUMIF($G:$G,B3,$H:$H) -> 0 | F3: =D3-E3 -> 2 | G3: PT. Yolita Plasinto Pratama ( Ida) | H3: 1 | I3: 2 | J3: 45386 | K3: - | L3: - | M3: -
A4: 3 | B4: Hendra Dwi Kurniawan | C4: 21/0227 | D4: 2 | E4: =SUMIF($G:$G,B4,$H:$H) -> 2 | F4: =D4-E4 -> 0 | G4: Hendra Dwi Kurniawan | H4: 1 | I4: 1 | J4: 45142
A5: 4 | B5: CV Jawa Indah (Ibu Yuli), Samarinda, Kal-Tim | C5: 21/0258 | D5: 2 | E5: =SUMIF($G:$G,B5,$H:$H) -> 1 | F5: =D5-E5 -> 1 | G5: Hendra Dwi Kurniawan | H5: 1 | I5: 2 | J5: 45255
A6: 5 | B6: PT. Yolita Plasinto Pratama ( Ida) | C6: PVE | D6: 2 | E6: =SUMIF($G:$G,B6,$H:$H) -> 2 | F6: =D6-E6 -> 0 | G6: CV Jawa Indah (Ibu Yuli), Samarinda, Kal-Tim | H6: 1 | I6: 1 | J6: 45176
A7: 6 | B7: CV Pije Peter Cheryl (Andi) | C7: 21/0455 | D7: 2 | E7: =SUMIF($G:$G,B7,$H:$H) -> 2 | F7: =D7-E7 -> 0 | G7: Iskandar 1 | H7: 1 | I7: 1 | J7: 45003
A8: 7 | B8: Esther Indrawati | C8: 21/0542 | D8: 2 | E8: =SUMIF($G:$G,B8,$H:$H) -> 2 | F8: =D8-E8 -> 0 | G8: Iskandar 1 | H8: 1 | I8: 2 | J8: 45097
A9: 8 | B9: PT. Bertie Sukses Makmur (Andi) | C9: 21/0375 | D9: 2 | E9: =SUMIF($G:$G,B9,$H:$H) -> 2 | F9: =D9-E9 -> 0 | G9: Iskandar 2 | H9: 1 | I9: 1 | J9: 45097
A10: 9 | B10: Ir. Pudjo Prihadi Santoso | C10: 21/0676 | D10: 2 | E10: =SUMIF($G:$G,B10,$H:$H) -> 2 | F10: =D10-E10 -> 0 | G10: Howard Kasima | H10: 1 | I10: 1 | J10: 14 Sept 2023
A11: 10 | B11: PT. Dwipar Loka Ayu (Aswin) | C11: 21/0599 | D11: 2 | E11: =SUMIF($G:$G,B11,$H:$H) -> 0 | F11: =D11-E11 -> 2 | G11: Howard Kasima | H11: 1 | I11: 2 | J11: 45492
A12: 11 | B12: Jenny Lie | C12: 21/0638 | D12: 2 | E12: =SUMIF($G:$G,B12,$H:$H) -> 0 | F12: =D12-E12 -> 2 | G12: Frans Andreas | H12: 1 | I12: 1 | J12: 45496
A13: 12 | B13: Herry Gunawan | C13: 21/0538 | D13: 2 | E13: =SUMIF($G:$G,B13,$H:$H) -> 2 | F13: =D13-E13 -> 0 | G13: Fahmuddin Edy Hadi, Yogjakarta | H13: 1 | I13: 1 | J13: 44764
A14: 13 | B14: Drg. Melanie Hendriaty | C14: 21/0570 | D14: 2 | E14: =SUMIF($G:$G,B14,$H:$H) -> 2 | F14: =D14-E14 -> 0 | G14: Fahmuddin Edy Hadi, Yogjakarta | H14: 1 | I14: 2 | J14: 45122
A15: 14 | B15: Iskandar 1 | C15: 21/0256 | D15: 2 | E15: =SUMIF($G:$G,B15,$H:$H) -> 2 | F15: =D15-E15 -> 0 | G15: PT. Bertie Sukses Makmur (Andi) | H15: 1 | I15: 1 | J15: 15 sept 2023
A16: 15 | B16: Thakurdas Pursani W | C16: 21/0740 | D16: 2 | E16: =SUMIF($G:$G,B16,$H:$H) -> 0 | F16: =D16-E16 -> 2 | G16: PT. Bertie Sukses Makmur (Andi) | H16: 1 | I16: 2 | J16: 45267
A17: 16 | B17: PT. Barnaby Kontruksi Sejahtera (Hilda) | C17: 21/0743 | D17: 2 | E17: =SUMIF($G:$G,B17,$H:$H) -> 0 | F17: =D17-E17 -> 2 | G17: CV Pije Peter Cheryl (Andi) | H17: 1 | I17: 1 | J17: 45210
A18: 17 | B18: Andy Indrajaya, ST | C18: 21/0791 | D18: 2 | E18: =SUMIF($G:$G,B18,$H:$H) -> 0 | F18: =D18-E18 -> 2 | G18: CV Pije Peter Cheryl (Andi) | H18: 1 | I18: 2 | J18: 45405
A19: 18 | B19: Fahmuddin Edy Hadi, Yogjakarta | C19: 21/0618 | D19: 2 | E19: =SUMIF($G:$G,B19,$H:$H) -> 2 | F19: =D19-E19 -> 0 | G19: Hasan Dali | H19: 1 | I19: 1 | J19: 44957
A20: 19 | B20: Hasan Dali | C20: 21/0879 | D20: 2 | E20: =SUMIF($G:$G,B20,$H:$H) -> 2 | F20: =D20-E20 -> 0 | G20: Hasan Dali | H20: 1 | I20: 2 | J20: 45303
A21: 20 | B21: Frans Andreas | C21: 21/0374 | D21: 2 | E21: =SUMIF($G:$G,B21,$H:$H) -> 1 | F21: =D21-E21 -> 1 | G21: Herry Gunawan | H21: 1 | I21: 1 | J21: 44945
A22: 21 | B22: Natalina Surjani .S | C22: 21/0916 | D22: 2 | E22: =SUMIF($G:$G,B22,$H:$H) -> 0 | F22: =D22-E22 -> 2 | G22: Herry Gunawan | H22: 1 | I22: 2 | J22: 45523
A23: 22 | B23: Yayasan Karya Kasih Mandiri (Sigit) | C23: 21/0901 | D23: 2 | E23: =SUMIF($G:$G,B23,$H:$H) -> 0 | F23: =D23-E23 -> 2 | G23: Mirza Budiman Diran | H23: 1 | I23: 1 | J23: 44985
A24: 23 | B24: Iskandar 2 | C24: 21/0256 | D24: 2 | E24: =SUMIF($G:$G,B24,$H:$H) -> 1 | F24: =D24-E24 -> 1 | G24: Mirza Budiman Diran | H24: 1 | I24: 2 | J24: 45275
A25: 24 | B25: Mirza Budiman Diran | C25: 21/0534 | D25: 2 | E25: =SUMIF($G:$G,B25,$H:$H) -> 2 | F25: =D25-E25 -> 0 | G25: Irawan Susanto | H25: 1 | I25: 1 | J25: 44939
A26: 25 | B26: PT. Esa Pratama (Hafzah) | C26: 21/0858 | D26: 2 | E26: =SUMIF($G:$G,B26,$H:$H) -> 0 | F26: =D26-E26 -> 2 | G26: Irawan Susanto | H26: 1 | I26: 2 | J26: 45397
A27: 26 | B27: PT Sumberdaya Indonesia (Andi Yusuf - Mangga) | C27: 192 | D27: 2 | E27: =SUMIF($G:$G,B27,$H:$H) -> 0 | F27: =D27-E27 -> 2 | G27: Esther Indrawati | H27: 1 | I27: 1 | J27: 45153
A28: 27 | B28: PT. Semesta Andesit Perkasa (Budi) - PT. Vicindo Jaya Makmur | C28: 21/1066 | D28: 2 | E28: =SUMIF($G:$G,B28,$H:$H) -> 0 | F28: =D28-E28 -> 2 | G28: Esther Indrawati | H28: 1 | I28: 2 | J28: 45499
A29: 28 | B29: Yayasan Perkembangan Anak Indonesia | C29: 21/0903 | D29: 2 | E29: =SUMIF($G:$G,B29,$H:$H) -> 0 | F29: =D29-E29 -> 2 | G29: Suryani | H29: 1 | I29: 1 | J29: 19 Sept 2023
A30: 29 | B30: Abednego Wibowo (Hartono) | C30: 21/1081 | D30: 2 | E30: =SUMIF($G:$G,B30,$H:$H) -> 0 | F30: =D30-E30 -> 2 | G30: Suryani | H30: 1 | I30: 2 | J30: 45378
A31: 30 | B31: M. Dodiek Tas'an Wartono | C31: 21/0994 | D31: 2 | E31: =SUMIF($G:$G,B31,$H:$H) -> 0 | F31: =D31-E31 -> 2 | G31: Felix Claudius Djimin (Greysia/ PT Kreasi Bintang Anugerah) | H31: 1 | I31: 1 | J31: 45153
A32: 31 | B32: Dr. Ketut Ananda W. Sp. OG (Klinik Ananda, Sumba) | C32: 21/0621 | D32: 2 | E32: =SUMIF($G:$G,B32,$H:$H) -> 0 | F32: =D32-E32 -> 2 | G32: Felix Claudius Djimin (Greysia/ PT Kreasi Bintang Anugerah) | H32: 1 | I32: 2 | J32: 45286
A33: 32 | B33: PT. Mitra Niaga Nusatama (Jelly) | C33: 21/0922 | D33: 2 | E33: =SUMIF($G:$G,B33,$H:$H) -> 0 | F33: =D33-E33 -> 2 | G33: Drg. Melanie Hendriaty | H33: 1 | I33: 1 | J33: 44812
A34: 33 | B34: Rajulur Rakhman | C34: 191 | D34: 2 | E34: =SUMIF($G:$G,B34,$H:$H) -> 0 | F34: =D34-E34 -> 2 | G34: Drg. Melanie Hendriaty | H34: 1 | I34: 2 | J34: 45105
A35: 34 | B35: PT. PT Duta Raya Cipta (Gulshan) | C35: 21/0857 | D35: 2 | E35: =SUMIF($G:$G,B35,$H:$H) -> 0 | F35: =D35-E35 -> 2 | G35: Ir. Pudjo Prihadi Santoso | H35: 1 | I35: 1 | J35: 44788
A36: 35 | B36: PT. Multilabindo Wahana (Hidayat) | C36: 21/0877 | D36: 2 | E36: =SUMIF($G:$G,B36,$H:$H) -> 0 | F36: =D36-E36 -> 2 | G36: Ir. Pudjo Prihadi Santoso | H36: 1 | I36: 2 | J36: 44929
A37: 36 | B37: Linda Irawati, Surabaya | C37: 188 | D37: 2 | E37: =SUMIF($G:$G,B37,$H:$H) -> 0 | F37: =D37-E37 -> 2
A38: 37 | B38: Linda Tjahja (Rivai) | C38: 21/1068 | D38: 2 | E38: =SUMIF($G:$G,B38,$H:$H) -> 0 | F38: =D38-E38 -> 2
A39: 38 | B39: PT. Dwi Tunggal Putra (Michael) | C39: 21/0962 | D39: 2 | E39: =SUMIF($G:$G,B39,$H:$H) -> 0 | F39: =D39-E39 -> 2
A40: 39 | B40: Djohan Surya Adinata | C40: 21/1147 | D40: 2 | E40: =SUMIF($G:$G,B40,$H:$H) -> 0 | F40: =D40-E40 -> 2
...

Sheet Counting Kontrak
A1: No | B1: Nama Cust | C1: Total Kontrak MC | D1: Total Kunjungan | E1: Sisa | F1: Nama Cust | G1: Kunjungan | H1: Kunjungan Ke - | I1: Visit Date | J1: Status | K1: Tech | L1: Report | M1: Note
A2: 1 | B2: Ir. H. Awan Hermawan Purwadinata MT, Bandung | D2: =SUMIF($F:$F,B2,$G:$G) -> 0 | E2: =C2-D2 -> 0 | F2: PT. Yolita Plasinto Pratama ( Ida) | G2: 1 | H2: 1
A3: 2 | B3: Syamsuardi Alpat (Sudirman) | D3: =SUMIF($F:$F,B3,$G:$G) -> 0 | E3: =C3-D3 -> 0 | F3: PT. First Marine Seafoods | G3: 1 | H3: 1
A4: 3 | B4: Hendra Dwi Kurniawan | D4: =SUMIF($F:$F,B4,$G:$G) -> 0 | E4: =C4-D4 -> 0 | F4: PT. First Marine Seafoods | G4: 1 | H4: 2
A5: 4 | B5: CV Jawa Indah (Ibu Yuli), Samarinda, Kal-Tim | D5: =SUMIF($F:$F,B5,$G:$G) -> 0 | E5: =C5-D5 -> 0
A6: 5 | B6: PT. Yolita Plasinto Pratama ( Ida) | C6: 14 | D6: =SUMIF($F:$F,B6,$G:$G) -> 1 | E6: =C6-D6 -> 13
A7: 6 | B7: CV Pije Peter Cheryl (Andi) | D7: =SUMIF($F:$F,B7,$G:$G) -> 0 | E7: =C7-D7 -> 0
A8: 7 | B8: Esther Indrawati | D8: =SUMIF($F:$F,B8,$G:$G) -> 0 | E8: =C8-D8 -> 0
A9: 8 | B9: PT. Bertie Sukses Makmur (Andi) | D9: =SUMIF($F:$F,B9,$G:$G) -> 0 | E9: =C9-D9 -> 0
A10: 9 | B10: Ir. Pudjo Prihadi Santoso | D10: =SUMIF($F:$F,B10,$G:$G) -> 0 | E10: =C10-D10 -> 0
A11: 10 | B11: PT. Dwipar Loka Ayu (Aswin) | D11: =SUMIF($F:$F,B11,$G:$G) -> 0 | E11: =C11-D11 -> 0
A12: 11 | B12: Jenny Lie | D12: =SUMIF($F:$F,B12,$G:$G) -> 0 | E12: =C12-D12 -> 0
A13: 12 | B13: Herry Gunawan | D13: =SUMIF($F:$F,B13,$G:$G) -> 0 | E13: =C13-D13 -> 0
A14: 13 | B14: Drg. Melanie Hendriaty | D14: =SUMIF($F:$F,B14,$G:$G) -> 0 | E14: =C14-D14 -> 0
A15: 14 | B15: Iskandar 1 | D15: =SUMIF($F:$F,B15,$G:$G) -> 0 | E15: =C15-D15 -> 0
A16: 15 | B16: Thakurdas Pursani W | D16: =SUMIF($F:$F,B16,$G:$G) -> 0 | E16: =C16-D16 -> 0
A17: 16 | B17: PT. Barnaby Kontruksi Sejahtera (Hilda) | D17: =SUMIF($F:$F,B17,$G:$G) -> 0 | E17: =C17-D17 -> 0
A18: 17 | B18: Andy Indrajaya, ST | D18: =SUMIF($F:$F,B18,$G:$G) -> 0 | E18: =C18-D18 -> 0
... A209: 208 | B209: Monica Pranata | D209: =SUMIF($F:$F,B209,$G:$G) -> 0 | E209: =C209-D209 -> 0
A210: 209 | B210: PT. First Marine Seafoods | C210: 7 | D210: =SUMIF($F:$F,B210,$G:$G) -> 2 | E210: =C210-D210 -> 5
A211: 210 | B211: Djoko Dermanto | D211: =SUMIF($F:$F,B211,$G:$G) -> 0 | E211: =C211-D211 -> 0
A212: 211 | B212: Andri Pekanbaru | D212: =SUMIF($F:$F,B212,$G:$G) -> 0 | E212: =C212-D212 -> 0
A213: 212 | B213: PT Primaperkasa Intiswadaya (Prayogo) | D213: =SUMIF($F:$F,B213,$G:$G) -> 0 | E213: =C213-D213 -> 0
A214: 213 | B214: PT Rukun Sahabat Senior | D214: =SUMIF($F:$F,B214,$G:$G) -> 0 | E214: =C214-D214 -> 0
A215: 214 | B215: Yesaya Milano - Situbondo | D215: =SUMIF($F:$F,B215,$G:$G) -> 0 | E215: =C215-D215 -> 0
A216: 215 | B216: YESAYA MALINO - Situbondo | D216: =SUMIF($F:$F,B216,$G:$G) -> 0 | E216: =C216-D216 -> 0
A217: 216 | B217: Ida Sofia SH-Gadog | D217: =SUMIF($F:$F,B217,$G:$G) -> 0 | E217: =C217-D217 -> 0
A218: 217 | B218: Dev - Pasar Baru | D218: =SUMIF($F:$F,B218,$G:$G) -> 0 | E218: =C218-D218 -> 0
A219: 218 | B219: PT. Swi Jetty Nusantara-Makassar | D219: =SUMIF($F:$F,B219,$G:$G) -> 0 | E219: =C219-D219 -> 0
A220: 219 | B220: Windri Lestari Rusli | D220: =SUMIF($F:$F,B220,$G:$G) -> 0 | E220: =C220-D220 -> 0
A221: 220 | B221: Mr. Jorge Serrano-Timor Leste | D221: =SUMIF($F:$F,B221,$G:$G) -> 0 | E221: =C221-D221 -> 0
A222: 221 | B222: Yudi Bandung | D222: =SUMIF($F:$F,B222,$G:$G) -> 0 | E222: =C222-D222 -> 0
... A365: 364 | B365: PT. Karya Perdana Baru ( Mandiri Hangtuah ) | D365: =SUMIF($F:$F,B365,$G:$G) -> 0 | E365: =C365-D365 -> 0

Sheet Tgl MC Free
A1: No | B1: Nama Cust | C1: Jenis Lift | D1: Code Lift | E1: Area | F1: BAST | G1: Tgl Maintenance 1 | H1: Status | I1: Tgl Maintenance Ke - 2 | J1: Status | K1: Tgl Maintenance ke -3 | L1: Status | M1: Maintenance Berjalan | O1: 180
A2: 1 | B2: Ir. H. Awan Hermawan Purwadinata MT, Bandung | C2: Domo Flex | D2: 21/0670 | E2: Bandung | F2: 45618 | G2: =F2+$O$1 -> 45798 | I2: =G2+$O$1 -> 45978 | M2: =IF(H2="Done",IF(J2="Done",IF(L2="Done","-",K2),I2),G2) -> 45798
A3: 2 | B3: Syamsuardi Alpat (Sudirman) | C3: Galactic | D3: 21/0745 | E3: Makasar | F3: 45620 | G3: =F3+$O$1 -> 45800 | I3: =G3+$O$1 -> 45980 | M3: =IF(H3="Done",IF(J3="Done",IF(L3="Done","-",K3),I3),G3) -> 45800
A4: 3 | B4: Hendra Dwi Kurniawan | C4: Domo Flex | D4: 21/0227 | E4: Jakarta Utara | F4: 45430 | G4: =F4+$O$1 -> 45610 | I4: =G4+$O$1 -> 45790 | M4: =IF(H4="Done",IF(J4="Done",IF(L4="Done","-",K4),I4),G4) -> 45610
A5: 4 | B5: CV Jawa Indah (Ibu Yuli), Samarinda, Kal-Tim | C5: Indomo Shaft | D5: 21/0258 | E5: Kalimantan Timur | F5: 45176 | G5: =F5+$O$1 -> 45356 | I5: =G5+$O$1 -> 45536 | M5: =IF(H5="Done",IF(J5="Done",IF(L5="Done","-",K5),I5),G5) -> 45356
A6: 5 | B6: PT. Yolita Plasinto Pratama ( Ida) | C6: Pve 37 midio | D6: PVE | E6: Jakarta Utara | F6: 45800 | G6: =F6+$O$1 -> 45980 | I6: =G6+$O$1 -> 46160 | M6: =IF(H6="Done",IF(J6="Done",IF(L6="Done","-",K6),I6),G6) -> 45980
A7: 6 | B7: CV Pije Peter Cheryl (Andi) | C7: Domo Flex | D7: 21/0455 | E7: Jakarta Selatan | F7: 45685 | G7: =F7+$O$1 -> 45865 | I7: =G7+$O$1 -> 46045 | M7: =IF(H7="Done",IF(J7="Done",IF(L7="Done","-",K7),I7),G7) -> 45865
A8: 7 | B8: Esther Indrawati | C8: Domo Flex | D8: 21/0542 | E8: Surabaya | F8: 45499 | G8: =F8+$O$1 -> 45679 | I8: =G8+$O$1 -> 45859 | M8: =IF(H8="Done",IF(J8="Done",IF(L8="Done","-",K8),I8),G8) -> 45679
A9: 8 | B9: PT. Bertie Sukses Makmur (Andi) | C9: Domo Flex | D9: 21/0375 | E9: Jakarta Selatan | F9: 45759 | G9: =F9+$O$1 -> 45939 | I9: =G9+$O$1 -> 46119 | M9: =IF(H9="Done",IF(J9="Done",IF(L9="Done","-",K9),I9),G9) -> 45939
A10: 9 | B10: Ir. Pudjo Prihadi Santoso | C10: Domo Flex | D10: 21/0676 | E10: Jakarta Selatan | F10: 45800 | G10: =F10+$O$1 -> 45980 | I10: =G10+$O$1 -> 46160 | M10: =IF(H10="Done",IF(J10="Done",IF(L10="Done","-",K10),I10),G10) -> 45980
A11: 10 | B11: PT. Dwipar Loka Ayu (Aswin) | C11: Domo Flex | D11: 21/0599 | E11: Jakarta Selatan | F11: 45798 | G11: =F11+$O$1 -> 45978 | I11: =G11+$O$1 -> 46158 | M11: =IF(H11="Done",IF(J11="Done",IF(L11="Done","-",K11),I11),G11) -> 45978
A12: 11 | B12: Jenny Lie | C12: Domo Flex | D12: 21/0638 | E12: Medan | F12: 45736 | G12: =F12+$O$1 -> 45916 | I12: =G12+$O$1 -> 46096 | M12: =IF(H12="Done",IF(J12="Done",IF(L12="Done","-",K12),I12),G12) -> 45916
A13: 12 | B13: Herry Gunawan | C13: Domo Flex | D13: 21/0538 | E13: Jawa Timur | F13: 45776 | G13: =F13+$O$1 -> 45956 | I13: =G13+$O$1 -> 46136 | M13: =IF(H13="Done",IF(J13="Done",IF(L13="Done","-",K13),I13),G13) -> 45956
... A26: 25 | B26: PT. Esa Pratama (Hafzah) | C26: Domo Flex | D26: 21/0858 | E26: Makassar | F26: 45374 | G26: =F26+$O$1 -> 45554 | I26: =G26+$O$1 -> 45734 | M26: =IF(H26="Done",IF(J26="Done",IF(L26="Done","-",K26),I26),G26) -> 45554
A27: 26 | B27: PT Sumberdaya Indonesia (Andi Yusuf - Mangga) | C27: Pve 37 midio | D27: 192 | E27: Jakarta Selatan | G27: =F27+$O$1 -> 180 | I27: =G27+$O$1 -> 360 | M27: =IF(H27="Done",IF(J27="Done",IF(L27="Done","-",K27),I27),G27) -> 180
A28: 27 | B28: PT. Semesta Andesit Perkasa (Budi) - PT. Vicindo Jaya Makmur | C28: Indomo Cabin | D28: 21/1066 | E28: Jakarta Utara | F28: 45800 | G28: =F28+$O$1 -> 45980 | I28: =G28+$O$1 -> 46160 | M28: =IF(H28="Done",IF(J28="Done",IF(L28="Done","-",K28),I28),G28) -> 45980
A29: 28 | B29: Yayasan Perkembangan Anak Indonesia | C29: Domo Flex | D29: 21/0903 | E29: Jakarta Selatan | F29: 45832 | G29: =F29+$O$1 -> 46012 | I29: =G29+$O$1 -> 46192 | M29: =IF(H29="Done",IF(J29="Done",IF(L29="Done","-",K29),I29),G29) -> 46012
